 * Running on http://127.0.0.1:5000/ (Press CTRL+C to quit)
 * Restarting with stat
 * Debugger is active!
 * Debugger PIN: 185-275-535
127.0.0.1 - - [29/Mar/2018 07:57:08] "GET / HTTP/1.1" 500 -
Traceback (most recent call last):
  File "/usr/local/lib/python3.5/dist-packages/flask/app.py", line 1997, in __call__
    return self.wsgi_app(environ, start_response)
  File "/usr/local/lib/python3.5/dist-packages/flask/app.py", line 1985, in wsgi_app
    response = self.handle_exception(e)
  File "/usr/local/lib/python3.5/dist-packages/flask/app.py", line 1540, in handle_exception
    reraise(exc_type, exc_value, tb)
  File "/usr/local/lib/python3.5/dist-packages/flask/_compat.py", line 33, in reraise
    raise value
  File "/usr/local/lib/python3.5/dist-packages/flask/app.py", line 1982, in wsgi_app
    response = self.full_dispatch_request()
  File "/usr/local/lib/python3.5/dist-packages/flask/app.py", line 1615, in full_dispatch_request
    return self.finalize_request(rv)
  File "/usr/local/lib/python3.5/dist-packages/flask/app.py", line 1630, in finalize_request
    response = self.make_response(rv)
  File "/usr/local/lib/python3.5/dist-packages/flask/app.py", line 1725, in make_response
    raise ValueError('View function did not return a response')
ValueError: View function did not return a response
127.0.0.1 - - [29/Mar/2018 07:57:10] "GET /?__debugger__=yes&cmd=resource&f=style.css HTTP/1.1" 200 -
127.0.0.1 - - [29/Mar/2018 07:57:10] "GET /?__debugger__=yes&cmd=resource&f=jquery.js HTTP/1.1" 200 -
127.0.0.1 - - [29/Mar/2018 07:57:10] "GET /?__debugger__=yes&cmd=resource&f=debugger.js HTTP/1.1" 200 -
127.0.0.1 - - [29/Mar/2018 07:57:10] "GET /?__debugger__=yes&cmd=resource&f=console.png HTTP/1.1" 200 -
127.0.0.1 - - [29/Mar/2018 07:57:11] "GET /?__debugger__=yes&cmd=resource&f=console.png HTTP/1.1" 200 -
127.0.0.1 - - [29/Mar/2018 08:10:00] "GET / HTTP/1.1" 500 -
Traceback (most recent call last):
  File "/usr/local/lib/python3.5/dist-packages/flask/app.py", line 1997, in __call__
    return self.wsgi_app(environ, start_response)
  File "/usr/local/lib/python3.5/dist-packages/flask/app.py", line 1985, in wsgi_app
    response = self.handle_exception(e)
  File "/usr/local/lib/python3.5/dist-packages/flask/app.py", line 1540, in handle_exception
    reraise(exc_type, exc_value, tb)
  File "/usr/local/lib/python3.5/dist-packages/flask/_compat.py", line 33, in reraise
    raise value
  File "/usr/local/lib/python3.5/dist-packages/flask/app.py", line 1982, in wsgi_app
    response = self.full_dispatch_request()
  File "/usr/local/lib/python3.5/dist-packages/flask/app.py", line 1615, in full_dispatch_request
    return self.finalize_request(rv)
  File "/usr/local/lib/python3.5/dist-packages/flask/app.py", line 1630, in finalize_request
    response = self.make_response(rv)
  File "/usr/local/lib/python3.5/dist-packages/flask/app.py", line 1725, in make_response
    raise ValueError('View function did not return a response')
ValueError: View function did not return a response
127.0.0.1 - - [29/Mar/2018 08:10:00] "GET /?__debugger__=yes&cmd=resource&f=jquery.js HTTP/1.1" 200 -
127.0.0.1 - - [29/Mar/2018 08:10:00] "GET /?__debugger__=yes&cmd=resource&f=style.css HTTP/1.1" 200 -
127.0.0.1 - - [29/Mar/2018 08:10:00] "GET /?__debugger__=yes&cmd=resource&f=debugger.js HTTP/1.1" 200 -
127.0.0.1 - - [29/Mar/2018 08:10:00] "GET /?__debugger__=yes&cmd=resource&f=console.png HTTP/1.1" 200 -
127.0.0.1 - - [29/Mar/2018 08:10:00] "GET /?__debugger__=yes&cmd=resource&f=console.png HTTP/1.1" 200 -
 * Detected change in '/home/shiyanlou/SYL/infomation_site/app.py', reloading
 * Restarting with stat
 * Debugger is active!
 * Debugger PIN: 185-275-535
127.0.0.1 - - [29/Mar/2018 08:15:45] "GET / HTTP/1.1" 500 -
Traceback (most recent call last):
  File "/usr/local/lib/python3.5/dist-packages/flask/app.py", line 1997, in __call__
    return self.wsgi_app(environ, start_response)
  File "/usr/local/lib/python3.5/dist-packages/flask/app.py", line 1985, in wsgi_app
    response = self.handle_exception(e)
  File "/usr/local/lib/python3.5/dist-packages/flask/app.py", line 1540, in handle_exception
    reraise(exc_type, exc_value, tb)
  File "/usr/local/lib/python3.5/dist-packages/flask/_compat.py", line 33, in reraise
    raise value
  File "/usr/local/lib/python3.5/dist-packages/flask/app.py", line 1982, in wsgi_app
    response = self.full_dispatch_request()
  File "/usr/local/lib/python3.5/dist-packages/flask/app.py", line 1614, in full_dispatch_request
    rv = self.handle_user_exception(e)
  File "/usr/local/lib/python3.5/dist-packages/flask/app.py", line 1517, in handle_user_exception
    reraise(exc_type, exc_value, tb)
  File "/usr/local/lib/python3.5/dist-packages/flask/_compat.py", line 33, in reraise
    raise value
  File "/usr/local/lib/python3.5/dist-packages/flask/app.py", line 1612, in full_dispatch_request
    rv = self.dispatch_request()
  File "/usr/local/lib/python3.5/dist-packages/flask/app.py", line 1598, in dispatch_request
    return self.view_functions[rule.endpoint](**req.view_args)
  File "/home/shiyanlou/SYL/infomation_site/app.py", line 30, in index
    index_html.get_json_content()
  File "/home/shiyanlou/SYL/infomation_site/app.py", line 21, in get_json_content
    content_dict[file] = json.load(ff)
  File "/usr/lib/python3.5/json/__init__.py", line 265, in load
    return loads(fp.read(),
AttributeError: 'str' object has no attribute 'read'
127.0.0.1 - - [29/Mar/2018 08:15:45] "GET /?__debugger__=yes&cmd=resource&f=style.css HTTP/1.1" 200 -
127.0.0.1 - - [29/Mar/2018 08:15:45] "GET /?__debugger__=yes&cmd=resource&f=jquery.js HTTP/1.1" 200 -
127.0.0.1 - - [29/Mar/2018 08:15:45] "GET /?__debugger__=yes&cmd=resource&f=debugger.js HTTP/1.1" 200 -
127.0.0.1 - - [29/Mar/2018 08:15:45] "GET /?__debugger__=yes&cmd=resource&f=console.png HTTP/1.1" 200 -
127.0.0.1 - - [29/Mar/2018 08:15:46] "GET /?__debugger__=yes&cmd=resource&f=console.png HTTP/1.1" 200 -
 * Detected change in '/home/shiyanlou/SYL/infomation_site/app.py', reloading
 * Restarting with stat
 * Debugger is active!
 * Debugger PIN: 185-275-535
127.0.0.1 - - [29/Mar/2018 08:26:13] "GET / HTTP/1.1" 500 -
Traceback (most recent call last):
  File "/usr/local/lib/python3.5/dist-packages/flask/app.py", line 1997, in __call__
    return self.wsgi_app(environ, start_response)
  File "/usr/local/lib/python3.5/dist-packages/flask/app.py", line 1985, in wsgi_app
    response = self.handle_exception(e)
  File "/usr/local/lib/python3.5/dist-packages/flask/app.py", line 1540, in handle_exception
    reraise(exc_type, exc_value, tb)
  File "/usr/local/lib/python3.5/dist-packages/flask/_compat.py", line 33, in reraise
    raise value
  File "/usr/local/lib/python3.5/dist-packages/flask/app.py", line 1982, in wsgi_app
    response = self.full_dispatch_request()
  File "/usr/local/lib/python3.5/dist-packages/flask/app.py", line 1614, in full_dispatch_request
    rv = self.handle_user_exception(e)
  File "/usr/local/lib/python3.5/dist-packages/flask/app.py", line 1517, in handle_user_exception
    reraise(exc_type, exc_value, tb)
  File "/usr/local/lib/python3.5/dist-packages/flask/_compat.py", line 33, in reraise
    raise value
  File "/usr/local/lib/python3.5/dist-packages/flask/app.py", line 1612, in full_dispatch_request
    rv = self.dispatch_request()
  File "/usr/local/lib/python3.5/dist-packages/flask/app.py", line 1598, in dispatch_request
    return self.view_functions[rule.endpoint](**req.view_args)
  File "/home/shiyanlou/SYL/infomation_site/app.py", line 30, in index
    return index_html.get_json_content()
  File "/home/shiyanlou/SYL/infomation_site/app.py", line 21, in get_json_content
    content_dict[file] = json.load(ff)
  File "/usr/lib/python3.5/json/__init__.py", line 265, in load
    return loads(fp.read(),
AttributeError: 'str' object has no attribute 'read'
127.0.0.1 - - [29/Mar/2018 08:26:13] "GET /?__debugger__=yes&cmd=resource&f=style.css HTTP/1.1" 200 -
127.0.0.1 - - [29/Mar/2018 08:26:13] "GET /?__debugger__=yes&cmd=resource&f=jquery.js HTTP/1.1" 200 -
127.0.0.1 - - [29/Mar/2018 08:26:13] "GET /?__debugger__=yes&cmd=resource&f=debugger.js HTTP/1.1" 200 -
127.0.0.1 - - [29/Mar/2018 08:26:13] "GET /?__debugger__=yes&cmd=resource&f=console.png HTTP/1.1" 200 -
127.0.0.1 - - [29/Mar/2018 08:26:14] "GET /?__debugger__=yes&cmd=resource&f=console.png HTTP/1.1" 200 -
 * Detected change in '/home/shiyanlou/SYL/infomation_site/app.py', reloading
 * Restarting with stat
 * Debugger is active!
 * Debugger PIN: 185-275-535
127.0.0.1 - - [29/Mar/2018 08:26:27] "GET / HTTP/1.1" 500 -
Traceback (most recent call last):
  File "/usr/local/lib/python3.5/dist-packages/flask/app.py", line 1997, in __call__
    return self.wsgi_app(environ, start_response)
  File "/usr/local/lib/python3.5/dist-packages/flask/app.py", line 1985, in wsgi_app
    response = self.handle_exception(e)
  File "/usr/local/lib/python3.5/dist-packages/flask/app.py", line 1540, in handle_exception
    reraise(exc_type, exc_value, tb)
  File "/usr/local/lib/python3.5/dist-packages/flask/_compat.py", line 33, in reraise
    raise value
  File "/usr/local/lib/python3.5/dist-packages/flask/app.py", line 1982, in wsgi_app
    response = self.full_dispatch_request()
  File "/usr/local/lib/python3.5/dist-packages/flask/app.py", line 1615, in full_dispatch_request
    return self.finalize_request(rv)
  File "/usr/local/lib/python3.5/dist-packages/flask/app.py", line 1630, in finalize_request
    response = self.make_response(rv)
  File "/usr/local/lib/python3.5/dist-packages/flask/app.py", line 1740, in make_response
    rv = self.response_class.force_type(rv, request.environ)
  File "/usr/local/lib/python3.5/dist-packages/werkzeug/wrappers.py", line 885, in force_type
    response = BaseResponse(*_run_wsgi_app(response, environ))
  File "/usr/local/lib/python3.5/dist-packages/werkzeug/wrappers.py", line 57, in _run_wsgi_app
    return _run_wsgi_app(*args)
  File "/usr/local/lib/python3.5/dist-packages/werkzeug/test.py", line 884, in run_wsgi_app
    app_rv = app(environ, start_response)
TypeError: 'dict' object is not callable
127.0.0.1 - - [29/Mar/2018 08:26:27] "GET /?__debugger__=yes&cmd=resource&f=debugger.js HTTP/1.1" 200 -
127.0.0.1 - - [29/Mar/2018 08:26:27] "GET /?__debugger__=yes&cmd=resource&f=jquery.js HTTP/1.1" 200 -
127.0.0.1 - - [29/Mar/2018 08:26:27] "GET /?__debugger__=yes&cmd=resource&f=style.css HTTP/1.1" 200 -
127.0.0.1 - - [29/Mar/2018 08:26:32] "GET /?__debugger__=yes&cmd=resource&f=console.png HTTP/1.1" 200 -
127.0.0.1 - - [29/Mar/2018 08:26:32] "GET /?__debugger__=yes&cmd=resource&f=console.png HTTP/1.1" 200 -
127.0.0.1 - - [29/Mar/2018 08:31:06] "GET / HTTP/1.1" 500 -
Traceback (most recent call last):
  File "/usr/local/lib/python3.5/dist-packages/flask/app.py", line 1997, in __call__
    return self.wsgi_app(environ, start_response)
  File "/usr/local/lib/python3.5/dist-packages/flask/app.py", line 1985, in wsgi_app
    response = self.handle_exception(e)
  File "/usr/local/lib/python3.5/dist-packages/flask/app.py", line 1540, in handle_exception
    reraise(exc_type, exc_value, tb)
  File "/usr/local/lib/python3.5/dist-packages/flask/_compat.py", line 33, in reraise
    raise value
  File "/usr/local/lib/python3.5/dist-packages/flask/app.py", line 1982, in wsgi_app
    response = self.full_dispatch_request()
  File "/usr/local/lib/python3.5/dist-packages/flask/app.py", line 1615, in full_dispatch_request
    return self.finalize_request(rv)
  File "/usr/local/lib/python3.5/dist-packages/flask/app.py", line 1630, in finalize_request
    response = self.make_response(rv)
  File "/usr/local/lib/python3.5/dist-packages/flask/app.py", line 1740, in make_response
    rv = self.response_class.force_type(rv, request.environ)
  File "/usr/local/lib/python3.5/dist-packages/werkzeug/wrappers.py", line 885, in force_type
    response = BaseResponse(*_run_wsgi_app(response, environ))
  File "/usr/local/lib/python3.5/dist-packages/werkzeug/test.py", line 884, in run_wsgi_app
    app_rv = app(environ, start_response)
TypeError: 'dict' object is not callable
127.0.0.1 - - [29/Mar/2018 08:31:06] "GET /?__debugger__=yes&cmd=resource&f=style.css HTTP/1.1" 200 -
127.0.0.1 - - [29/Mar/2018 08:31:06] "GET /?__debugger__=yes&cmd=resource&f=debugger.js HTTP/1.1" 200 -
127.0.0.1 - - [29/Mar/2018 08:31:06] "GET /?__debugger__=yes&cmd=resource&f=jquery.js HTTP/1.1" 200 -
127.0.0.1 - - [29/Mar/2018 08:31:07] "GET /?__debugger__=yes&cmd=resource&f=console.png HTTP/1.1" 200 -
127.0.0.1 - - [29/Mar/2018 08:31:07] "GET /?__debugger__=yes&cmd=resource&f=console.png HTTP/1.1" 200 -
 * Detected change in '/home/shiyanlou/SYL/infomation_site/app.py', reloading
 * Restarting with stat
 * Debugger is active!
 * Debugger PIN: 185-275-535
127.0.0.1 - - [29/Mar/2018 08:31:55] "GET / HTTP/1.1" 500 -
Traceback (most recent call last):
  File "/usr/local/lib/python3.5/dist-packages/flask/app.py", line 1997, in __call__
    return self.wsgi_app(environ, start_response)
  File "/usr/local/lib/python3.5/dist-packages/flask/app.py", line 1985, in wsgi_app
    response = self.handle_exception(e)
  File "/usr/local/lib/python3.5/dist-packages/flask/app.py", line 1540, in handle_exception
    reraise(exc_type, exc_value, tb)
  File "/usr/local/lib/python3.5/dist-packages/flask/_compat.py", line 33, in reraise
    raise value
  File "/usr/local/lib/python3.5/dist-packages/flask/app.py", line 1982, in wsgi_app
    response = self.full_dispatch_request()
  File "/usr/local/lib/python3.5/dist-packages/flask/app.py", line 1615, in full_dispatch_request
    return self.finalize_request(rv)
  File "/usr/local/lib/python3.5/dist-packages/flask/app.py", line 1630, in finalize_request
    response = self.make_response(rv)
  File "/usr/local/lib/python3.5/dist-packages/flask/app.py", line 1725, in make_response
    raise ValueError('View function did not return a response')
ValueError: View function did not return a response
127.0.0.1 - - [29/Mar/2018 08:31:55] "GET /?__debugger__=yes&cmd=resource&f=debugger.js HTTP/1.1" 200 -
127.0.0.1 - - [29/Mar/2018 08:31:55] "GET /?__debugger__=yes&cmd=resource&f=jquery.js HTTP/1.1" 200 -
127.0.0.1 - - [29/Mar/2018 08:31:55] "GET /?__debugger__=yes&cmd=resource&f=style.css HTTP/1.1" 200 -
127.0.0.1 - - [29/Mar/2018 08:32:00] "GET /?__debugger__=yes&cmd=resource&f=console.png HTTP/1.1" 200 -
127.0.0.1 - - [29/Mar/2018 08:32:00] "GET /?__debugger__=yes&cmd=resource&f=console.png HTTP/1.1" 200 -
 * Detected change in '/home/shiyanlou/SYL/infomation_site/app.py', reloading
{'/home/shiyanlou/SYL/infomation_site/files/helloshiyanlou.json': {'created_time': '2017-09-09 12:00:00', 'title': 'Hello, Shiyanlou!', 'content': 'Welcome to shiyanlou.com \\n This is shiyanlou.com louplus demo page. \\n Please let us know if you have any questions \\n Thank you!'}, '/home/shiyanlou/SYL/infomation_site/files/helloworld.json': {'created_time': '2017-08-09 12:00:00', 'title': 'Hello, World!', 'content': 'Hello world! \\\\n This is hello world demo page. \\\\n Please let us know if you have any questions \\\\n Thank you!'}}
 * Restarting with stat
 * Debugger is active!
 * Debugger PIN: 185-275-535
127.0.0.1 - - [29/Mar/2018 08:32:34] "GET / HTTP/1.1" 500 -
Traceback (most recent call last):
  File "/usr/local/lib/python3.5/dist-packages/flask/app.py", line 1997, in __call__
    return self.wsgi_app(environ, start_response)
  File "/usr/local/lib/python3.5/dist-packages/flask/app.py", line 1985, in wsgi_app
    response = self.handle_exception(e)
  File "/usr/local/lib/python3.5/dist-packages/flask/app.py", line 1540, in handle_exception
    reraise(exc_type, exc_value, tb)
  File "/usr/local/lib/python3.5/dist-packages/flask/_compat.py", line 33, in reraise
    raise value
  File "/usr/local/lib/python3.5/dist-packages/flask/app.py", line 1982, in wsgi_app
    response = self.full_dispatch_request()
  File "/usr/local/lib/python3.5/dist-packages/flask/app.py", line 1615, in full_dispatch_request
    return self.finalize_request(rv)
  File "/usr/local/lib/python3.5/dist-packages/flask/app.py", line 1630, in finalize_request
    response = self.make_response(rv)
  File "/usr/local/lib/python3.5/dist-packages/flask/app.py", line 1740, in make_response
    rv = self.response_class.force_type(rv, request.environ)
  File "/usr/local/lib/python3.5/dist-packages/werkzeug/wrappers.py", line 885, in force_type
    response = BaseResponse(*_run_wsgi_app(response, environ))
  File "/usr/local/lib/python3.5/dist-packages/werkzeug/wrappers.py", line 57, in _run_wsgi_app
    return _run_wsgi_app(*args)
  File "/usr/local/lib/python3.5/dist-packages/werkzeug/test.py", line 884, in run_wsgi_app
    app_rv = app(environ, start_response)
TypeError: 'dict' object is not callable
127.0.0.1 - - [29/Mar/2018 08:32:34] "GET /?__debugger__=yes&cmd=resource&f=style.css HTTP/1.1" 200 -
127.0.0.1 - - [29/Mar/2018 08:32:34] "GET /?__debugger__=yes&cmd=resource&f=jquery.js HTTP/1.1" 200 -
127.0.0.1 - - [29/Mar/2018 08:32:34] "GET /?__debugger__=yes&cmd=resource&f=debugger.js HTTP/1.1" 200 -
127.0.0.1 - - [29/Mar/2018 08:32:34] "GET /?__debugger__=yes&cmd=resource&f=console.png HTTP/1.1" 200 -
127.0.0.1 - - [29/Mar/2018 08:32:34] "GET /?__debugger__=yes&cmd=resource&f=console.png HTTP/1.1" 200 -
 * Detected change in '/home/shiyanlou/SYL/infomation_site/app.py', reloading
 * Restarting with stat
 * Debugger is active!
 * Debugger PIN: 185-275-535
127.0.0.1 - - [29/Mar/2018 08:35:04] "GET / HTTP/1.1" 500 -
Traceback (most recent call last):
  File "/usr/local/lib/python3.5/dist-packages/flask/app.py", line 1997, in __call__
    return self.wsgi_app(environ, start_response)
  File "/usr/local/lib/python3.5/dist-packages/flask/app.py", line 1985, in wsgi_app
    response = self.handle_exception(e)
  File "/usr/local/lib/python3.5/dist-packages/flask/app.py", line 1540, in handle_exception
    reraise(exc_type, exc_value, tb)
  File "/usr/local/lib/python3.5/dist-packages/flask/_compat.py", line 33, in reraise
    raise value
  File "/usr/local/lib/python3.5/dist-packages/flask/app.py", line 1982, in wsgi_app
    response = self.full_dispatch_request()
  File "/usr/local/lib/python3.5/dist-packages/flask/app.py", line 1615, in full_dispatch_request
    return self.finalize_request(rv)
  File "/usr/local/lib/python3.5/dist-packages/flask/app.py", line 1630, in finalize_request
    response = self.make_response(rv)
  File "/usr/local/lib/python3.5/dist-packages/flask/app.py", line 1740, in make_response
    rv = self.response_class.force_type(rv, request.environ)
  File "/usr/local/lib/python3.5/dist-packages/werkzeug/wrappers.py", line 885, in force_type
    response = BaseResponse(*_run_wsgi_app(response, environ))
  File "/usr/local/lib/python3.5/dist-packages/werkzeug/wrappers.py", line 57, in _run_wsgi_app
    return _run_wsgi_app(*args)
  File "/usr/local/lib/python3.5/dist-packages/werkzeug/test.py", line 884, in run_wsgi_app
    app_rv = app(environ, start_response)
TypeError: 'dict' object is not callable
127.0.0.1 - - [29/Mar/2018 08:35:04] "GET /?__debugger__=yes&cmd=resource&f=style.css HTTP/1.1" 200 -
127.0.0.1 - - [29/Mar/2018 08:35:04] "GET /?__debugger__=yes&cmd=resource&f=debugger.js HTTP/1.1" 200 -
127.0.0.1 - - [29/Mar/2018 08:35:04] "GET /?__debugger__=yes&cmd=resource&f=jquery.js HTTP/1.1" 200 -
127.0.0.1 - - [29/Mar/2018 08:35:04] "GET /?__debugger__=yes&cmd=resource&f=console.png HTTP/1.1" 200 -
127.0.0.1 - - [29/Mar/2018 08:35:04] "GET /?__debugger__=yes&cmd=resource&f=console.png HTTP/1.1" 200 -
 * Detected change in '/home/shiyanlou/SYL/infomation_site/app.py', reloading
 * Restarting with stat
 * Debugger is active!
 * Debugger PIN: 185-275-535
127.0.0.1 - - [29/Mar/2018 08:51:10] "GET / HTTP/1.1" 500 -
Traceback (most recent call last):
  File "/usr/local/lib/python3.5/dist-packages/flask/app.py", line 1997, in __call__
    return self.wsgi_app(environ, start_response)
  File "/usr/local/lib/python3.5/dist-packages/flask/app.py", line 1985, in wsgi_app
    response = self.handle_exception(e)
  File "/usr/local/lib/python3.5/dist-packages/flask/app.py", line 1540, in handle_exception
    reraise(exc_type, exc_value, tb)
  File "/usr/local/lib/python3.5/dist-packages/flask/_compat.py", line 33, in reraise
    raise value
  File "/usr/local/lib/python3.5/dist-packages/flask/app.py", line 1982, in wsgi_app
    response = self.full_dispatch_request()
  File "/usr/local/lib/python3.5/dist-packages/flask/app.py", line 1615, in full_dispatch_request
    return self.finalize_request(rv)
  File "/usr/local/lib/python3.5/dist-packages/flask/app.py", line 1630, in finalize_request
    response = self.make_response(rv)
  File "/usr/local/lib/python3.5/dist-packages/flask/app.py", line 1740, in make_response
    rv = self.response_class.force_type(rv, request.environ)
  File "/usr/local/lib/python3.5/dist-packages/werkzeug/wrappers.py", line 885, in force_type
    response = BaseResponse(*_run_wsgi_app(response, environ))
  File "/usr/local/lib/python3.5/dist-packages/werkzeug/wrappers.py", line 57, in _run_wsgi_app
    return _run_wsgi_app(*args)
  File "/usr/local/lib/python3.5/dist-packages/werkzeug/test.py", line 884, in run_wsgi_app
    app_rv = app(environ, start_response)
TypeError: 'dict' object is not callable
127.0.0.1 - - [29/Mar/2018 08:51:11] "GET /?__debugger__=yes&cmd=resource&f=style.css HTTP/1.1" 200 -
127.0.0.1 - - [29/Mar/2018 08:51:11] "GET /?__debugger__=yes&cmd=resource&f=debugger.js HTTP/1.1" 200 -
127.0.0.1 - - [29/Mar/2018 08:51:11] "GET /?__debugger__=yes&cmd=resource&f=jquery.js HTTP/1.1" 200 -
127.0.0.1 - - [29/Mar/2018 08:51:11] "GET /?__debugger__=yes&cmd=resource&f=console.png HTTP/1.1" 200 -
127.0.0.1 - - [29/Mar/2018 08:51:11] "GET /?__debugger__=yes&cmd=resource&f=console.png HTTP/1.1" 200 -
 * Detected change in '/home/shiyanlou/SYL/infomation_site/app.py', reloading
 * Restarting with stat
 * Debugger is active!
 * Debugger PIN: 185-275-535
127.0.0.1 - - [29/Mar/2018 08:52:10] "GET / HTTP/1.1" 500 -
Traceback (most recent call last):
  File "/usr/local/lib/python3.5/dist-packages/flask/app.py", line 1997, in __call__
    return self.wsgi_app(environ, start_response)
  File "/usr/local/lib/python3.5/dist-packages/flask/app.py", line 1985, in wsgi_app
    response = self.handle_exception(e)
  File "/usr/local/lib/python3.5/dist-packages/flask/app.py", line 1540, in handle_exception
    reraise(exc_type, exc_value, tb)
  File "/usr/local/lib/python3.5/dist-packages/flask/_compat.py", line 33, in reraise
    raise value
  File "/usr/local/lib/python3.5/dist-packages/flask/app.py", line 1982, in wsgi_app
    response = self.full_dispatch_request()
  File "/usr/local/lib/python3.5/dist-packages/flask/app.py", line 1615, in full_dispatch_request
    return self.finalize_request(rv)
  File "/usr/local/lib/python3.5/dist-packages/flask/app.py", line 1630, in finalize_request
    response = self.make_response(rv)
  File "/usr/local/lib/python3.5/dist-packages/flask/app.py", line 1740, in make_response
    rv = self.response_class.force_type(rv, request.environ)
  File "/usr/local/lib/python3.5/dist-packages/werkzeug/wrappers.py", line 885, in force_type
    response = BaseResponse(*_run_wsgi_app(response, environ))
  File "/usr/local/lib/python3.5/dist-packages/werkzeug/wrappers.py", line 57, in _run_wsgi_app
    return _run_wsgi_app(*args)
  File "/usr/local/lib/python3.5/dist-packages/werkzeug/test.py", line 884, in run_wsgi_app
    app_rv = app(environ, start_response)
TypeError: 'dict' object is not callable
127.0.0.1 - - [29/Mar/2018 08:52:10] "GET /?__debugger__=yes&cmd=resource&f=style.css HTTP/1.1" 200 -
127.0.0.1 - - [29/Mar/2018 08:52:10] "GET /?__debugger__=yes&cmd=resource&f=jquery.js HTTP/1.1" 200 -
127.0.0.1 - - [29/Mar/2018 08:52:10] "GET /?__debugger__=yes&cmd=resource&f=debugger.js HTTP/1.1" 200 -
127.0.0.1 - - [29/Mar/2018 08:52:10] "GET /?__debugger__=yes&cmd=resource&f=console.png HTTP/1.1" 200 -
127.0.0.1 - - [29/Mar/2018 08:52:10] "GET /?__debugger__=yes&cmd=resource&f=console.png HTTP/1.1" 200 -
 * Detected change in '/home/shiyanlou/SYL/infomation_site/app.py', reloading
 * Restarting with stat
 * Debugger is active!
 * Debugger PIN: 185-275-535
 * Detected change in '/home/shiyanlou/SYL/infomation_site/app.py', reloading
 * Restarting with stat
 * Debugger is active!
 * Debugger PIN: 185-275-535
 * Detected change in '/home/shiyanlou/SYL/infomation_site/app.py', reloading
 * Restarting with stat
 * Debugger is active!
 * Debugger PIN: 185-275-535
127.0.0.1 - - [29/Mar/2018 09:15:06] "GET / HTTP/1.1" 500 -
Traceback (most recent call last):
  File "/usr/local/lib/python3.5/dist-packages/flask/app.py", line 1997, in __call__
    return self.wsgi_app(environ, start_response)
  File "/usr/local/lib/python3.5/dist-packages/flask/app.py", line 1985, in wsgi_app
    response = self.handle_exception(e)
  File "/usr/local/lib/python3.5/dist-packages/flask/app.py", line 1540, in handle_exception
    reraise(exc_type, exc_value, tb)
  File "/usr/local/lib/python3.5/dist-packages/flask/_compat.py", line 33, in reraise
    raise value
  File "/usr/local/lib/python3.5/dist-packages/flask/app.py", line 1982, in wsgi_app
    response = self.full_dispatch_request()
  File "/usr/local/lib/python3.5/dist-packages/flask/app.py", line 1615, in full_dispatch_request
    return self.finalize_request(rv)
  File "/usr/local/lib/python3.5/dist-packages/flask/app.py", line 1630, in finalize_request
    response = self.make_response(rv)
  File "/usr/local/lib/python3.5/dist-packages/flask/app.py", line 1740, in make_response
    rv = self.response_class.force_type(rv, request.environ)
  File "/usr/local/lib/python3.5/dist-packages/werkzeug/wrappers.py", line 885, in force_type
    response = BaseResponse(*_run_wsgi_app(response, environ))
  File "/usr/local/lib/python3.5/dist-packages/werkzeug/wrappers.py", line 57, in _run_wsgi_app
    return _run_wsgi_app(*args)
  File "/usr/local/lib/python3.5/dist-packages/werkzeug/test.py", line 884, in run_wsgi_app
    app_rv = app(environ, start_response)
TypeError: 'dict' object is not callable
127.0.0.1 - - [29/Mar/2018 09:15:06] "GET /?__debugger__=yes&cmd=resource&f=style.css HTTP/1.1" 200 -
127.0.0.1 - - [29/Mar/2018 09:15:06] "GET /?__debugger__=yes&cmd=resource&f=debugger.js HTTP/1.1" 200 -
127.0.0.1 - - [29/Mar/2018 09:15:06] "GET /?__debugger__=yes&cmd=resource&f=jquery.js HTTP/1.1" 200 -
127.0.0.1 - - [29/Mar/2018 09:15:06] "GET /?__debugger__=yes&cmd=resource&f=console.png HTTP/1.1" 200 -
127.0.0.1 - - [29/Mar/2018 09:15:06] "GET /?__debugger__=yes&cmd=resource&f=console.png HTTP/1.1" 200 -
127.0.0.1 - - [29/Mar/2018 09:17:45] "GET / HTTP/1.1" 500 -
Traceback (most recent call last):
  File "/usr/local/lib/python3.5/dist-packages/flask/app.py", line 1997, in __call__
    return self.wsgi_app(environ, start_response)
  File "/usr/local/lib/python3.5/dist-packages/flask/app.py", line 1985, in wsgi_app
    response = self.handle_exception(e)
  File "/usr/local/lib/python3.5/dist-packages/flask/app.py", line 1540, in handle_exception
    reraise(exc_type, exc_value, tb)
  File "/usr/local/lib/python3.5/dist-packages/flask/_compat.py", line 33, in reraise
    raise value
  File "/usr/local/lib/python3.5/dist-packages/flask/app.py", line 1982, in wsgi_app
    response = self.full_dispatch_request()
  File "/usr/local/lib/python3.5/dist-packages/flask/app.py", line 1615, in full_dispatch_request
    return self.finalize_request(rv)
  File "/usr/local/lib/python3.5/dist-packages/flask/app.py", line 1630, in finalize_request
    response = self.make_response(rv)
  File "/usr/local/lib/python3.5/dist-packages/flask/app.py", line 1740, in make_response
    rv = self.response_class.force_type(rv, request.environ)
  File "/usr/local/lib/python3.5/dist-packages/werkzeug/wrappers.py", line 885, in force_type
    response = BaseResponse(*_run_wsgi_app(response, environ))
  File "/usr/local/lib/python3.5/dist-packages/werkzeug/test.py", line 884, in run_wsgi_app
    app_rv = app(environ, start_response)
TypeError: 'dict' object is not callable
127.0.0.1 - - [29/Mar/2018 09:17:45] "GET /?__debugger__=yes&cmd=resource&f=style.css HTTP/1.1" 200 -
127.0.0.1 - - [29/Mar/2018 09:17:45] "GET /?__debugger__=yes&cmd=resource&f=jquery.js HTTP/1.1" 200 -
127.0.0.1 - - [29/Mar/2018 09:17:45] "GET /?__debugger__=yes&cmd=resource&f=debugger.js HTTP/1.1" 200 -
127.0.0.1 - - [29/Mar/2018 09:17:45] "GET /?__debugger__=yes&cmd=resource&f=console.png HTTP/1.1" 200 -
127.0.0.1 - - [29/Mar/2018 09:17:45] "GET /?__debugger__=yes&cmd=resource&f=console.png HTTP/1.1" 200 -
127.0.0.1 - - [29/Mar/2018 09:20:29] "GET / HTTP/1.1" 500 -
Traceback (most recent call last):
  File "/usr/local/lib/python3.5/dist-packages/flask/app.py", line 1997, in __call__
    return self.wsgi_app(environ, start_response)
  File "/usr/local/lib/python3.5/dist-packages/flask/app.py", line 1985, in wsgi_app
    response = self.handle_exception(e)
  File "/usr/local/lib/python3.5/dist-packages/flask/app.py", line 1540, in handle_exception
    reraise(exc_type, exc_value, tb)
  File "/usr/local/lib/python3.5/dist-packages/flask/_compat.py", line 33, in reraise
    raise value
  File "/usr/local/lib/python3.5/dist-packages/flask/app.py", line 1982, in wsgi_app
    response = self.full_dispatch_request()
  File "/usr/local/lib/python3.5/dist-packages/flask/app.py", line 1615, in full_dispatch_request
    return self.finalize_request(rv)
  File "/usr/local/lib/python3.5/dist-packages/flask/app.py", line 1630, in finalize_request
    response = self.make_response(rv)
  File "/usr/local/lib/python3.5/dist-packages/flask/app.py", line 1740, in make_response
    rv = self.response_class.force_type(rv, request.environ)
  File "/usr/local/lib/python3.5/dist-packages/werkzeug/wrappers.py", line 885, in force_type
    response = BaseResponse(*_run_wsgi_app(response, environ))
  File "/usr/local/lib/python3.5/dist-packages/werkzeug/test.py", line 884, in run_wsgi_app
    app_rv = app(environ, start_response)
TypeError: 'dict' object is not callable
127.0.0.1 - - [29/Mar/2018 09:20:29] "GET /?__debugger__=yes&cmd=resource&f=style.css HTTP/1.1" 200 -
127.0.0.1 - - [29/Mar/2018 09:20:29] "GET /?__debugger__=yes&cmd=resource&f=jquery.js HTTP/1.1" 200 -
127.0.0.1 - - [29/Mar/2018 09:20:29] "GET /?__debugger__=yes&cmd=resource&f=debugger.js HTTP/1.1" 200 -
127.0.0.1 - - [29/Mar/2018 09:20:29] "GET /?__debugger__=yes&cmd=resource&f=console.png HTTP/1.1" 200 -
127.0.0.1 - - [29/Mar/2018 09:20:30] "GET /?__debugger__=yes&cmd=resource&f=console.png HTTP/1.1" 200 -
 * Detected change in '/home/shiyanlou/SYL/infomation_site/app.py', reloading
 * Restarting with stat
 * Debugger is active!
 * Debugger PIN: 185-275-535
127.0.0.1 - - [29/Mar/2018 09:21:42] "GET / HTTP/1.1" 200 -
127.0.0.1 - - [29/Mar/2018 09:21:42] "GET /favicon.ico HTTP/1.1" 404 -
127.0.0.1 - - [29/Mar/2018 09:21:43] "GET /favicon.ico HTTP/1.1" 404 -
